2020-03-22 14:05:10,225 [INFO ]  Starting Rasa server on http://localhost:5005
2020-03-22 14:20:53,747 [INFO ]  Starting Rasa server on http://localhost:5005
2020-03-22 14:41:06,599 [ERROR]  Exception occurred while handling uri: 'http://2c40bb09.ngrok.io/favicon.ico'
Traceback (most recent call last):
  File "/home/raaz/chatbot/lib/python3.6/site-packages/sanic/app.py", line 940, in handle_request
    handler, args, kwargs, uri, name = self.router.get(request)
  File "/home/raaz/chatbot/lib/python3.6/site-packages/sanic/router.py", line 411, in get
    return self._get(request.path, request.method, "")
  File "/home/raaz/chatbot/lib/python3.6/site-packages/sanic/router.py", line 475, in _get
    raise NotFound("Requested URL {} not found".format(url))
sanic.exceptions.NotFound: Requested URL /favicon.ico not found
2020-03-22 14:49:18,710 [INFO ]  Starting Rasa server on http://localhost:5005
2020-03-22 14:51:32,949 [INFO ]  Starting Rasa server on http://localhost:5005
2020-03-22 15:45:38,641 [INFO ]  Starting Rasa server on http://localhost:5005
2020-03-22 15:46:30,890 [INFO ]  Starting Rasa server on http://localhost:5005
2020-03-22 15:46:39,053 [ERROR]  Unable to start server
Traceback (most recent call last):
  File "/home/raaz/chatbot/lib/python3.6/site-packages/sanic/server.py", line 895, in serve
    http_server = loop.run_until_complete(server_coroutine)
  File "uvloop/loop.pyx", line 1456, in uvloop.loop.Loop.run_until_complete
  File "uvloop/loop.pyx", line 1727, in create_server
OSError: [Errno 98] error while attempting to bind on address ('0.0.0.0', 5005): address already in use
